Workbook

Sheet PBC Personnel
A1: # | B1: Role | C1: Count | D1: Type | E1: Phase | F1: Salary Low | G1: Salary High | H1: Salary Mid | I1: Fringe Rate | J1: Fringe Cost | K1: Fully Loaded | L1: Total Low | M1: Total High | N1: Total Mid
B2: LEADERSHIP
A3: 1 | B3: Founder and CEO (Dee Williams) | C3: 1 | D3: Full-Time | E3: Now | F3: 200000 | G3: 300000 | H3: =AVERAGE(F3,G3) -> 250000 | I3: 0.25 | J3: =H3*I3 -> 62500 | K3: =H3+J3 -> 312500 | L3: =F3*C3 -> 200000 | M3: =G3*C3 -> 300000 | N3: =K3*C3 -> 312500
A4: 2 | B4: Chief Science Officer | C4: 1 | D4: Full-Time | E4: Yr 2 | F4: 250000 | G4: 350000 | H4: =AVERAGE(F4,G4) -> 300000 | I4: 0.25 | J4: =H4*I4 -> 75000 | K4: =H4+J4 -> 375000 | L4: =F4*C4 -> 250000 | M4: =G4*C4 -> 350000 | N4: =K4*C4 -> 375000
A5: 3 | B5: Chief of Staff to CEO | C5: 1 | D5: Full-Time | E5: Yr 2 | F5: 150000 | G5: 200000 | H5: =AVERAGE(F5,G5) -> 175000 | I5: 0.25 | J5: =H5*I5 -> 43750 | K5: =H5+J5 -> 218750 | L5: =F5*C5 -> 150000 | M5: =G5*C5 -> 200000 | N5: =K5*C5 -> 218750
B6: RESEARCH
A7: 4 | B7: Director of Research | C7: 1 | D7: Full-Time | E7: Yr 1 | F7: 220000 | G7: 300000 | H7: =AVERAGE(F7,G7) -> 260000 | I7: 0.25 | J7: =H7*I7 -> 65000 | K7: =H7+J7 -> 325000 | L7: =F7*C7 -> 220000 | M7: =G7*C7 -> 300000 | N7: =K7*C7 -> 325000
A8: 5 | B8: Pillar Lead: Post-Deployment Behavior | C8: 1 | D8: Full-Time | E8: Yr 1 | F8: 170000 | G8: 230000 | H8: =AVERAGE(F8,G8) -> 200000 | I8: 0.25 | J8: =H8*I8 -> 50000 | K8: =H8+J8 -> 250000 | L8: =F8*C8 -> 170000 | M8: =G8*C8 -> 230000 | N8: =K8*C8 -> 250000
A9: 6 | B9: Pillar Lead: Runtime Research | C9: 1 | D9: Full-Time | E9: Yr 1 | F9: 170000 | G9: 230000 | H9: =AVERAGE(F9,G9) -> 200000 | I9: 0.25 | J9: =H9*I9 -> 50000 | K9: =H9+J9 -> 250000 | L9: =F9*C9 -> 170000 | M9: =G9*C9 -> 230000 | N9: =K9*C9 -> 250000
A10: 7 | B10: Pillar Lead: Interaction Dynamics | C10: 1 | D10: Full-Time | E10: Yr 1 | F10: 170000 | G10: 230000 | H10: =AVERAGE(F10,G10) -> 200000 | I10: 0.25 | J10: =H10*I10 -> 50000 | K10: =H10+J10 -> 250000 | L10: =F10*C10 -> 170000 | M10: =G10*C10 -> 230000 | N10: =K10*C10 -> 250000
A11: 8 | B11: Pillar Lead: Substrate Governance | C11: 1 | D11: Full-Time | E11: Yr 1 | F11: 170000 | G11: 230000 | H11: =AVERAGE(F11,G11) -> 200000 | I11: 0.25 | J11: =H11*I11 -> 50000 | K11: =H11+J11 -> 250000 | L11: =F11*C11 -> 170000 | M11: =G11*C11 -> 230000 | N11: =K11*C11 -> 250000
A12: 9 | B12: Pillar Lead: Multi-Agent Safety | C12: 1 | D12: Full-Time | E12: Yr 1 | F12: 170000 | G12: 230000 | H12: =AVERAGE(F12,G12) -> 200000 | I12: 0.25 | J12: =H12*I12 -> 50000 | K12: =H12+J12 -> 250000 | L12: =F12*C12 -> 170000 | M12: =G12*C12 -> 230000 | N12: =K12*C12 -> 250000
A13: 10 | B13: Research Analyst 1 | C13: 1 | D13: Full-Time | E13: Yr 1 | F13: 95000 | G13: 135000 | H13: =AVERAGE(F13,G13) -> 115000 | I13: 0.25 | J13: =H13*I13 -> 28750 | K13: =H13+J13 -> 143750 | L13: =F13*C13 -> 95000 | M13: =G13*C13 -> 135000 | N13: =K13*C13 -> 143750
A14: 11 | B14: Research Analyst 2 | C14: 1 | D14: Full-Time | E14: Yr 1 | F14: 95000 | G14: 135000 | H14: =AVERAGE(F14,G14) -> 115000 | I14: 0.25 | J14: =H14*I14 -> 28750 | K14: =H14+J14 -> 143750 | L14: =F14*C14 -> 95000 | M14: =G14*C14 -> 135000 | N14: =K14*C14 -> 143750
A15: 12 | B15: Research Analyst 3 | C15: 1 | D15: Full-Time | E15: Yr 1 | F15: 95000 | G15: 135000 | H15: =AVERAGE(F15,G15) -> 115000 | I15: 0.25 | J15: =H15*I15 -> 28750 | K15: =H15+J15 -> 143750 | L15: =F15*C15 -> 95000 | M15: =G15*C15 -> 135000 | N15: =K15*C15 -> 143750
A16: 13 | B16: Research Program Manager | C16: 1 | D16: Full-Time | E16: Yr 1 | F16: 120000 | G16: 160000 | H16: =AVERAGE(F16,G16) -> 140000 | I16: 0.25 | J16: =H16*I16 -> 35000 | K16: =H16+J16 -> 175000 | L16: =F16*C16 -> 120000 | M16: =G16*C16 -> 160000 | N16: =K16*C16 -> 175000
A17: 14 | B17: Research Editor | C17: 1 | D17: Full-Time | E17: Yr 1 | F17: 85000 | G17: 120000 | H17: =AVERAGE(F17,G17) -> 102500 | I17: 0.25 | J17: =H17*I17 -> 25625 | K17: =H17+J17 -> 128125 | L17: =F17*C17 -> 85000 | M17: =G17*C17 -> 120000 | N17: =K17*C17 -> 128125
A18: 15 | B18: Behavioral Health Adviser | C18: 1 | D18: Part-Time | E18: Yr 1 | F18: 40000 | G18: 60000 | H18: =AVERAGE(F18,G18) -> 50000 | I18: 0.25 | J18: =H18*I18 -> 12500 | K18: =H18+J18 -> 62500 | L18: =F18*C18 -> 40000 | M18: =G18*C18 -> 60000 | N18: =K18*C18 -> 62500
... A20: 17 | B20: IRB / Research Ethics Officer | C20: 1 | D20: Consultant | E20: Yr 1 | F20: 30000 | G20: 50000 | H20: =AVERAGE(F20,G20) -> 40000 | I20: 0.25 | J20: =H20*I20 -> 10000 | K20: =H20+J20 -> 50000 | L20: =F20*C20 -> 30000 | M20: =G20*C20 -> 50000 | N20: =K20*C20 -> 50000
B21: TECHNOLOGY
A22: 18 | B22: Lead Engineer | C22: 1 | D22: Full-Time | E22: Yr 1 | F22: 200000 | G22: 275000 | H22: =AVERAGE(F22,G22) -> 237500 | I22: 0.25 | J22: =H22*I22 -> 59375 | K22: =H22+J22 -> 296875 | L22: =F22*C22 -> 200000 | M22: =G22*C22 -> 275000 | N22: =K22*C22 -> 296875
A23: 19 | B23: Data Engineer | C23: 1 | D23: Full-Time | E23: Yr 1 | F23: 155000 | G23: 210000 | H23: =AVERAGE(F23,G23) -> 182500 | I23: 0.25 | J23: =H23*I23 -> 45625 | K23: =H23+J23 -> 228125 | L23: =F23*C23 -> 155000 | M23: =G23*C23 -> 210000 | N23: =K23*C23 -> 228125
A24: 20 | B24: IT / Systems Administrator | C24: 1 | D24: Part-Time | E24: Yr 1 | F24: 45000 | G24: 65000 | H24: =AVERAGE(F24,G24) -> 55000 | I24: 0.25 | J24: =H24*I24 -> 13750 | K24: =H24+J24 -> 68750 | L24: =F24*C24 -> 45000 | M24: =G24*C24 -> 65000 | N24: =K24*C24 -> 68750
A25: 21 | B25: DevSecOps / Security Engineer | C25: 1 | D25: Full-Time | E25: Yr 2 | F25: 160000 | G25: 220000 | H25: =AVERAGE(F25,G25) -> 190000 | I25: 0.25 | J25: =H25*I25 -> 47500 | K25: =H25+J25 -> 237500 | L25: =F25*C25 -> 160000 | M25: =G25*C25 -> 220000 | N25: =K25*C25 -> 237500
B26: PARTNERSHIPS AND SALES
A27: 22 | B27: Head of Strategic Partnerships | C27: 1 | D27: Full-Time | E27: Yr 1 | F27: 150000 | G27: 200000 | H27: =AVERAGE(F27,G27) -> 175000 | I27: 0.25 | J27: =H27*I27 -> 43750 | K27: =H27+J27 -> 218750 | L27: =F27*C27 -> 150000 | M27: =G27*C27 -> 200000 | N27: =K27*C27 -> 218750
A28: 23 | B28: Corporate Partnerships Rep | C28: 1 | D28: Full-Time | E28: Yr 1 | F28: 100000 | G28: 140000 | H28: =AVERAGE(F28,G28) -> 120000 | I28: 0.25 | J28: =H28*I28 -> 30000 | K28: =H28+J28 -> 150000 | L28: =F28*C28 -> 100000 | M28: =G28*C28 -> 140000 | N28: =K28*C28 -> 150000
A29: 24 | B29: Head of AI Policy / Gov Relations | C29: 1 | D29: Full-Time | E29: Yr 2 | F29: 150000 | G29: 200000 | H29: =AVERAGE(F29,G29) -> 175000 | I29: 0.25 | J29: =H29*I29 -> 43750 | K29: =H29+J29 -> 218750 | L29: =F29*C29 -> 150000 | M29: =G29*C29 -> 200000 | N29: =K29*C29 -> 218750
A30: 25 | B30: Head of Academic Relations | C30: 1 | D30: Full-Time | E30: Yr 2 | F30: 140000 | G30: 180000 | H30: =AVERAGE(F30,G30) -> 160000 | I30: 0.25 | J30: =H30*I30 -> 40000 | K30: =H30+J30 -> 200000 | L30: =F30*C30 -> 140000 | M30: =G30*C30 -> 180000 | N30: =K30*C30 -> 200000
B31: EVENTS
A32: 26 | B32: Events Director | C32: 1 | D32: Full-Time | E32: Yr 1 | F32: 110000 | G32: 150000 | H32: =AVERAGE(F32,G32) -> 130000 | I32: 0.25 | J32: =H32*I32 -> 32500 | K32: =H32+J32 -> 162500 | L32: =F32*C32 -> 110000 | M32: =G32*C32 -> 150000 | N32: =K32*C32 -> 162500
A33: 27 | B33: Events Coordinator | C33: 1 | D33: Full-Time | E33: Yr 1 | F33: 65000 | G33: 90000 | H33: =AVERAGE(F33,G33) -> 77500 | I33: 0.25 | J33: =H33*I33 -> 19375 | K33: =H33+J33 -> 96875 | L33: =F33*C33 -> 65000 | M33: =G33*C33 -> 90000 | N33: =K33*C33 -> 96875
B34: COMMUNITY AND CONTENT
A35: 28 | B35: Community Director | C35: 1 | D35: Full-Time | E35: Yr 1 | F35: 130000 | G35: 175000 | H35: =AVERAGE(F35,G35) -> 152500 | I35: 0.25 | J35: =H35*I35 -> 38125 | K35: =H35+J35 -> 190625 | L35: =F35*C35 -> 130000 | M35: =G35*C35 -> 175000 | N35: =K35*C35 -> 190625
A36: 29 | B36: Content and Communications Lead | C36: 1 | D36: Full-Time | E36: Yr 1 | F36: 110000 | G36: 150000 | H36: =AVERAGE(F36,G36) -> 130000 | I36: 0.25 | J36: =H36*I36 -> 32500 | K36: =H36+J36 -> 162500 | L36: =F36*C36 -> 110000 | M36: =G36*C36 -> 150000 | N36: =K36*C36 -> 162500
A37: 30 | B37: Fellowship Growth Manager | C37: 1 | D37: Full-Time | E37: Yr 1 | F37: 95000 | G37: 135000 | H37: =AVERAGE(F37,G37) -> 115000 | I37: 0.25 | J37: =H37*I37 -> 28750 | K37: =H37+J37 -> 143750 | L37: =F37*C37 -> 95000 | M37: =G37*C37 -> 135000 | N37: =K37*C37 -> 143750
A38: 31 | B38: PR and Media Relations Manager | C38: 1 | D38: Full-Time | E38: Yr 1 | F38: 115000 | G38: 155000 | H38: =AVERAGE(F38,G38) -> 135000 | I38: 0.25 | J38: =H38*I38 -> 33750 | K38: =H38+J38 -> 168750 | L38: =F38*C38 -> 115000 | M38: =G38*C38 -> 155000 | N38: =K38*C38 -> 168750
A39: 32 | B39: Multimedia / Video Producer | C39: 1 | D39: Full-Time | E39: Yr 2 | F39: 90000 | G39: 130000 | H39: =AVERAGE(F39,G39) -> 110000 | I39: 0.25 | J39: =H39*I39 -> 27500 | K39: =H39+J39 -> 137500 | L39: =F39*C39 -> 90000 | M39: =G39*C39 -> 130000 | N39: =K39*C39 -> 137500
B40: CREATIVE
A41: 33 | B41: Creative Director | C41: 1 | D41: Full-Time | E41: Yr 1 | F41: 140000 | G41: 185000 | H41: =AVERAGE(F41,G41) -> 162500 | I41: 0.25 | J41: =H41*I41 -> 40625 | K41: =H41+J41 -> 203125 | L41: =F41*C41 -> 140000 | M41: =G41*C41 -> 185000 | N41: =K41*C41 -> 203125
...

Sheet PBC Operations
A1: Category | B1: Annual Low | C1: Annual High | D1: Annual Mid | E1: Notes
A2: Office Space (Marina del Rey, 47 people) | B2: 300000 | C2: 600000 | D2: =AVERAGE(B2,C2) -> 450000 | E2: Lease, utilities, buildout
A3: Technology Infrastructure | B3: 200000 | C3: 400000 | D3: =AVERAGE(B3,C3) -> 300000 | E3: Hosting, cloud, platform dev tools
A4: Events Production (27-30 events/yr) | B4: 500000 | C4: 1500000 | D4: =AVERAGE(B4,C4) -> 1000000 | E4: Venues, catering, AV, logistics
A5: Legal and Insurance | B5: 200000 | C5: 400000 | D5: =AVERAGE(B5,C5) -> 300000 | E5: D&O, E&O, liability, IP counsel
A6: Marketing and Advertising | B6: 200000 | C6: 400000 | D6: =AVERAGE(B6,C6) -> 300000 | E6: Digital, print, conference marketing
A7: Travel | B7: 150000 | C7: 300000 | D7: =AVERAGE(B7,C7) -> 225000 | E7: Staff travel, conference attendance
A8: Equipment and Supplies | B8: 100000 | C8: 200000 | D8: =AVERAGE(B8,C8) -> 150000 | E8: Computers, office supplies, hardware
A9: Software and Subscriptions | B9: 100000 | C9: 200000 | D9: =AVERAGE(B9,C9) -> 150000 | E9: SaaS, research tools, licenses
A10: Miscellaneous / Contingency | B10: 150000 | C10: 300000 | D10: =AVERAGE(B10,C10) -> 225000 | E10: 10% buffer
A11: TOTAL PBC OPERATIONS | B11: =SUM(B2:B10) -> 1900000 | C11: =SUM(C2:C10) -> 4300000 | D11: =SUM(D2:D10) -> 3100000

Sheet PBC Revenue
A1: # | B1: Revenue Stream | C1: Frequency | D1: Type | E1: Year 1 Low | F1: Year 1 High | G1: Year 1 Mid | H1: Year 3 Target | I1: Assumptions
B2: GRANTS (Direct to PBC)
A3: 1 | B3: SBIR/STTR Grants (NSF, DOE, DARPA) | C3: Per cycle | D3: Grants | E3: 500000 | F3: 1500000 | G3: =AVERAGE(E3,F3) -> 1000000 | H3: 0 | I3: Phase I $275K, Phase II $1M. Target 2 applications Year 1.
A4: 2 | B4: State Innovation Grants (CalOSBA) | C4: Rolling | D4: Grants | E4: 50000 | F4: 200000 | G4: =AVERAGE(E4,F4) -> 125000 | H4: 0 | I4: Multiple state programs. $25K to $100K each.
A5: 3 | B5: Corporate Sponsored Research | C5: Ongoing | D5: Grants | E5: 350000 | F5: 500000 | G5: =AVERAGE(E5,F5) -> 425000 | H5: 0 | I5: 3 to 5 corporate sponsors funding specific pillar research. $75K to $150K per sponsorship.
B6: EVALUATIONS AND ASSESSMENTS
A7: 4 | B7: Post-Deployment Safety Audits | C7: Ongoing | D7: Earned | E7: 500000 | F7: 1000000 | G7: =AVERAGE(E7,F7) -> 750000 | H7: 0 | I7: $25K to $100K per audit. Two sales reps. 10 engagements at $50K avg = $500K low.
A8: 5 | B8: Regulatory Readiness Assessments | C8: Ongoing | D8: Earned | E8: 350000 | F8: 500000 | G8: =AVERAGE(E8,F8) -> 425000 | H8: 0 | I8: $10K to $50K per assessment. AI regulation driving urgent demand. 15 assessments at $23K avg.
B9: PARTNERSHIPS
A10: 6 | B10: Corporate Research Partnerships | C10: Annual | D10: Earned | E10: 750000 | F10: 2000000 | G10: =AVERAGE(E10,F10) -> 1375000 | H10: 0 | I10: $25K to $50K annual membership. Two dedicated reps. 20 partners at $25K = $500K floor. 30 at $25K = $750K low.
B11: CONFERENCES AND EVENTS
A12: 7 | B12: PRISM Summit (in-person annual) | C12: Annual | D12: Earned | E12: 1000000 | F12: 1500000 | G12: =AVERAGE(E12,F12) -> 1250000 | H12: 0 | I12: 300 attendees at $500 to $1500. 15 to 25 sponsors at $10K to $100K. Merch. Activations. Dee: at least $1M.
A13: 8 | B13: Virtual Conferences (1 to 2/yr) | C13: 1 to 2/yr | D13: Earned | E13: 200000 | F13: 500000 | G13: =AVERAGE(E13,F13) -> 350000 | H13: 0 | I13: $100 to $500 tickets. Lower overhead. Sponsors. Global reach.
A14: 9 | B14: Golf Tournaments (4/yr championship) | C14: 4/yr | D14: Earned | E14: 400000 | F14: 1000000 | G14: =AVERAGE(E14,F14) -> 700000 | H14: 0 | I14: $100K to $250K per tournament. Tickets, foursomes, sponsors, prizes.
A15: 10 | B15: Round Tables (monthly) | C15: 12/yr | D15: Earned | E15: 360000 | F15: 1200000 | G15: =AVERAGE(E15,F15) -> 780000 | H15: 0 | I15: $2.5K to $5K per seat. 12 to 20 seats. 12 per year. High-value intimate format.
A16: 11 | B16: Think Tanks (5/yr) | C16: 5/yr | D16: Earned | E16: 250000 | F16: 750000 | G16: =AVERAGE(E16,F16) -> 500000 | H16: 0 | I16: $5K to $10K per seat. 10 to 15 seats. Exclusive. Final one at Summit.
A17: 12 | B17: Hackathon / Challenge Event | C17: 1 to 2/yr | D17: Earned | E17: 200000 | F17: 500000 | G17: =AVERAGE(E17,F17) -> 350000 | H17: 0 | I17: Sponsors fund prizes. Entry fees. Media coverage.
A18: 13 | B18: Telethons / Webathons (1 to 2/yr) | C18: 1 to 2/yr | D18: Earned | E18: 200000 | F18: 500000 | G18: =AVERAGE(E18,F18) -> 350000 | H18: 0 | I18: Live fundraising events. Community driven.
A19: 14 | B19: Retreats (1 to 2/yr) | C19: 1 to 2/yr | D19: Earned | E19: 200000 | F19: 500000 | G19: =AVERAGE(E19,F19) -> 350000 | H19: 0 | I19: $5K to $10K per attendee. 20 to 50 people. Training component.
B20: CERTIFICATION AND TRAINING
A21: 15 | B21: Certification Program | C21: Ongoing | D21: Earned | E21: 700000 | F21: 2000000 | G21: =AVERAGE(E21,F21) -> 1350000 | H21: 0 | I21: $2K to $5K per cert. Enterprise teams send cohorts of 10 to 20. 200 certs at $3.5K avg = $700K low.
A22: 16 | B22: Learning Academy (paid advanced) | C22: Ongoing | D22: Earned | E22: 300000 | F22: 750000 | G22: =AVERAGE(E22,F22) -> 525000 | H22: 0 | I22: Free portal drives leads. Paid advanced classes $200 to $2K. University partnerships.
B23: PRODUCTS AND COMMUNITY
A24: 17 | B24: Annual Industry Report | C24: Annual | D24: Earned | E24: 400000 | F24: 1000000 | G24: =AVERAGE(E24,F24) -> 700000 | H24: 0 | I24: $5K to $25K per enterprise copy. First-of-its-kind AI safety report. 40 buyers at $10K avg = $400K low.
A25: 18 | B25: Digital Products / Lead Magnets | C25: Ongoing | D25: Earned | E25: 100000 | F25: 300000 | G25: =AVERAGE(E25,F25) -> 200000 | H25: 0 | I25: Guides, frameworks, templates, toolkits. Top of funnel.
A26: 19 | B26: Online Community / Paid Membership | C26: Monthly | D26: Earned | E26: 300000 | F26: 600000 | G26: =AVERAGE(E26,F26) -> 450000 | H26: 0 | I26: Tiered membership. 500 to 2000 members at $25 to $100/month avg.
A27: 20 | B27: Merchandise | C27: Ongoing | D27: Earned | E27: 100000 | F27: 300000 | G27: =AVERAGE(E27,F27) -> 200000 | H27: 0 | I27: PRISM branded. Conference merch. Online store.
B29: TOTAL PBC REVENUE | E29: =SUM(E2:E27) -> 7210000 | F29: =SUM(F2:F27) -> 17100000 | G29: =SUM(G2:G27) -> 12155000 | H29: =SUM(H2:H27) -> 0
B30: Grants Subtotal | E30: =E3+E4+E5 -> 900000 | F30: =F3+F4+F5 -> 2200000 | G30: =G3+G4+G5 -> 1550000
B31: Earned Revenue Subtotal | E31: =E7+E8+E10+E12+E13+E14+E15+E16+E17+E18+E19+E21+E22+E24+E25+E26+E27 -> 6310000 | F31: =F7+F8+F10+F12+F13+F14+F15+F16+F17+F18+F19+F21+F22+F24+F25+F26+F27 -> 14900000 | G31: =G7+G8+G10+G12+G13+G14+G15+G16+G17+G18+G19+G21+G22+G24+G25+G26+G27 -> 10605000

Sheet PBC Summary
A1: AUDACION AI LABS PBC
A2: Financial Summary
B4: Low | C4: High | D4: Mid
A5: EXPENSES
A6: Personnel (44 roles, fully loaded at 25%) | B6: ='PBC Personnel'!L57 -> 5257000 | C6: ='PBC Personnel'!M57 -> 7273000 | D6: ='PBC Personnel'!N57 -> 7831250
A7: Operations | B7: ='PBC Operations'!B11 -> 1900000 | C7: ='PBC Operations'!C11 -> 4300000 | D7: ='PBC Operations'!D11 -> 3100000
A8: TOTAL PBC EXPENSES | B8: =B6+B7 -> 7157000 | C8: =C6+C7 -> 11573000 | D8: =D6+D7 -> 10931250
A10: REVENUE
A11: Grants (SBIR, State, Corporate) | B11: ='PBC Revenue'!E30 -> 900000 | C11: ='PBC Revenue'!F30 -> 2200000 | D11: ='PBC Revenue'!G30 -> 1550000
A12: Earned Revenue (17 streams) | B12: ='PBC Revenue'!E31 -> 6310000 | C12: ='PBC Revenue'!F31 -> 14900000 | D12: ='PBC Revenue'!G31 -> 10605000
A13: Contract Revenue from Nonprofit | B13: 0 | C13: 0 | D13: 0
A14: TOTAL PBC REVENUE | B14: =B11+B12+B13 -> 7210000 | C14: =C11+C12+C13 -> 17100000 | D14: =D11+D12+D13 -> 12155000
A16: NET (Revenue minus Expenses) | B16: =B14-B8 -> 53000 | C16: =C14-C8 -> 5527000 | D16: =D14-D8 -> 1223750
